Workbook
Name SlicerCache_Table_2_Col_1: #N/A

Sheet Sheet1
B1: Pujianto | C1: MBP
B2: Alfi Syahri | C2: CME
B3: Harun Nurasyid | C3: CME | E3: Cell down | F3: Corrective | G3: Replace Optik,RRU/Soket Power/Replace GPS | H3: P1
B4: Nurhayat | C4: MBP | E4: Vswr | F4: Corrective | G4: Replace Jumper,antena/RRU | H4: P1
B5: Putra wardana | C5: TE | E5: Site Down | F5: Corrective | G5: Pemadaman,MCB Trip,Transmisi problem | H5: P1
B6: Sailillah | C6: TE | E6: Eas Validation | F6: Preventive | G6: integrasi LAN dan validasi alarm | H6: P2
B7: Tiviansyah | C7: TE | E7: PM | F7: Preventive | G7: Preventive Maintenance | H7: P2
B8: Rio ardinata | C8: MBP | E8: Support Event | F8: Corrective | G8: =E8 -> Support Event | H8: P2
B9: munawir akhmad | C9: TE | E9: Pengawalan Team telkom | F9: Preventive | G9: Akses/Hub Site problem metro | H9: P2
B10: Ahmad Muzakir | C10: MBP | E10: Pengawalan akses Vendor | F10: Preventive | G10: =E10 -> Pengawalan akses Vendor | H10: P3
B11: Murjani | C11: TE | E11: Pengecekan battrey | F11: Preventive | G11: Pengukuran dan pengambilan data log serta input Gdoc BBT | H11: P2
B12: Purwanto | C12: MBP | E12: Pengecekan Suhu Shelter | F12: Preventive | G12: =E12 -> Pengecekan Suhu Shelter | H12: P1
B13: Adi Bowo Santoso | C13: TE | E13: Replace FAN Rectifier | F13: Corrective | G13: =E13 -> Replace FAN Rectifier | H13: P1
B14: Ahmad Setiawan | C14: TE | E14: Add Sector RRU | F14: Corrective | G14: Add New Sector antena/rru | H14: P2
B15: Fahmi | C15: TE | E15: Repointing MW | F15: Corrective | G15: Impact BTS down / RX Level >70 / PL | H15: P1
B16: Agus muliana pamungkas | C16: MBP | E16: Pemasangan battrey | F16: Preventive | G16: Instalasi Battery | H16: P2
B17: Sairaji | C17: MBP | E17: Pengecekan/Pergantian BFAN BTS | F17: Preventive | G17: Bts High temp impact fliker | H17: P2
B18: Yahya Muhamad | C18: TE | E18: Pengecekan Power | F18: Preventive | G18: MCB trip/Power upnormal | H18: P1
B19: hory yusmanto | C19: MBP | E19: Penambahan Modul Recti | F19: Corrective | G19: =E19 -> Penambahan Modul Recti | H19: P2
B20: melky.O.Tulangow | C20: TE | E20: Deinstal Repeater | F20: Corrective | G20: =E20 -> Deinstal Repeater | H20: P2
B21: Muhammad Mukti | C21: TE | E21: Instalasi Smallcell | F21: Corrective | G21: =E21 -> Instalasi Smallcell | H21: P3
B22: Reynaldy Ricardo Putra | C22: TE | E22: Perbaikan Exhaust fan | F22: Corrective | G22: =E22 -> Perbaikan Exhaust fan | H22: P3
B23: Sahrul Saputra | C23: TE | E23: Pengecekan BSC | F23: Preventive | G23: =E23 -> Pengecekan BSC | H23: P1
B24: Fajrianur wahid | C24: TE | E24: Standby On Call | F24: Standby | G24: =E24 -> Standby On Call | H24: P3
B25: Elia Ronaldo | C25: TE | E25: On Leave | F25: =E25 -> On Leave | G25: =E25 -> On Leave | H25: P3
B26: Aulia Rahman | C26: TE | E26: Sick | F26: =E26 -> Sick | G26: =E26 -> Sick | H26: P3
B27: Leonard | C27: TE | E27: Tshoot Genset | F27: Corrective | G27: Perbaikan Auto,pergantian relay,timer, yang berhubungan genset | H27: P1
B28: Armadi | C28: TE
B29: Sarwono | C29: CME
B30: Ahmad | C30: TE
B31: james jimbris | C31: TE
B32: Jumadi | C32: TE
B33: Muhamad Rayhan | C33: TE
B34: Oky Bangkit Pamungkas | C34: TE
B35: AHMAD ARDIANTO FIRMANSYAH | C35: PM
B36: Darli | C36: PM
B37: Indra | C37: PM
B38: Khilal dawai katiri | C38: MBP
B39: Trisno Susanto | C39: PM
... B46: Armadi | C46: TE

Sheet Summary

Sheet to do list
A3: Category Task | B3: Prioritas | C3: Site ID | D3: FME Name | E3: Role | F3: RTS Name | G3: Cluster | H3: Category Activity | I3: Detail Activity | J3: Activity | K3: Start Date | L3: End Date | M3: Status Task | N3: Remark | O3: Column 15 | P3: Column 16
A4: Standby On Call | B4: =IFERROR(VLOOKUP(A4,Sheet1!$E$3:$H$27,4,0),"") -> P3 | D4: Putra wardana | E4: =IFERROR(VLOOKUP(D4,Sheet1!$B$1:$C$45,2,0),"") -> TE | F4: Winda Sokenda | G4: =IFERROR(IFS(F4="Winda Sokenda","Barito Raya",F4="Doni Damara","Palangkaraya"),"") -> Barito Raya | H4: =IFERROR(VLOOKUP(A4,Sheet1!$E$3:$F$27,2,),"") -> Standby | I4: =IFERROR(VLOOKUP(A4,Sheet1!$E$3:$G$27,3,0),"") -> Standby On Call | J4: Standby | K4: 46315 | L4: 46315 | M4: Done | N4: Stanby
A5: Pengecekan Power | B5: =IFERROR(VLOOKUP(A5,Sheet1!$E$3:$H$27,4,0),"") -> P1 | C5: NTH149 | D5: Sailillah | E5: =IFERROR(VLOOKUP(D5,Sheet1!$B$1:$C$45,2,0),"") -> TE | F5: Winda Sokenda | G5: =IFERROR(IFS(F5="Winda Sokenda","Barito Raya",F5="Doni Damara","Palangkaraya"),"") -> Barito Raya | H5: =IFERROR(VLOOKUP(A5,Sheet1!$E$3:$F$27,2,),"") -> Preventive | I5: =IFERROR(VLOOKUP(A5,Sheet1!$E$3:$G$27,3,0),"") -> MCB trip/Power upnormal | J5: On Progress | K5: 46315 | L5: 46315 | M5: Done | N5: Isi token & PMS done
A6: Sick | B6: =IFERROR(VLOOKUP(A6,Sheet1!$E$3:$H$27,4,0),"") -> P3 | D6: Tiviansyah | E6: =IFERROR(VLOOKUP(D6,Sheet1!$B$1:$C$45,2,0),"") -> TE | F6: Winda Sokenda | G6: =IFERROR(IFS(F6="Winda Sokenda","Barito Raya",F6="Doni Damara","Palangkaraya"),"") -> Barito Raya | H6: =IFERROR(VLOOKUP(A6,Sheet1!$E$3:$F$27,2,),"") -> Sick | I6: =IFERROR(VLOOKUP(A6,Sheet1!$E$3:$G$27,3,0),"") -> Sick | J6: Standby | K6: 46315 | L6: 46315 | M6: Done | N6: Izin sakit
A7: Site Down | B7: =IFERROR(VLOOKUP(A7,Sheet1!$E$3:$H$27,4,0),"") -> P1 | C7: COH937 | D7: munawir akhmad | E7: =IFERROR(VLOOKUP(D7,Sheet1!$B$1:$C$45,2,0),"") -> TE | F7: Winda Sokenda | G7: =IFERROR(IFS(F7="Winda Sokenda","Barito Raya",F7="Doni Damara","Palangkaraya"),"") -> Barito Raya | H7: =IFERROR(VLOOKUP(A7,Sheet1!$E$3:$F$27,2,),"") -> Corrective | I7: =IFERROR(VLOOKUP(A7,Sheet1!$E$3:$G$27,3,0),"") -> Pemadaman,MCB Trip,Transmisi problem | J7: On Progress | K7: 46315 | L7: 46315 | M7: Done | N7: PLN off, kawal team telkom MTW248
A8: Site Down | B8: =IFERROR(VLOOKUP(A8,Sheet1!$E$3:$H$27,4,0),"") -> P1 | C8: PRC038 | D8: Murjani | E8: =IFERROR(VLOOKUP(D8,Sheet1!$B$1:$C$45,2,0),"") -> TE | F8: Winda Sokenda | G8: =IFERROR(IFS(F8="Winda Sokenda","Barito Raya",F8="Doni Damara","Palangkaraya"),"") -> Barito Raya | H8: =IFERROR(VLOOKUP(A8,Sheet1!$E$3:$F$27,2,),"") -> Corrective | I8: =IFERROR(VLOOKUP(A8,Sheet1!$E$3:$G$27,3,0),"") -> Pemadaman,MCB Trip,Transmisi problem | J8: On Progress | K8: 46315 | L8: 46315 | M8: Done | N8: Replace RRU
A9: Tshoot Genset | B9: =IFERROR(VLOOKUP(A9,Sheet1!$E$3:$H$27,4,0),"") -> P1 | C9: KKP305 | D9: Reynaldy Ricardo Putra | E9: =IFERROR(VLOOKUP(D9,Sheet1!$B$1:$C$45,2,0),"") -> TE | F9: Winda Sokenda | G9: =IFERROR(IFS(F9="Winda Sokenda","Barito Raya",F9="Doni Damara","Palangkaraya"),"") -> Barito Raya | H9: =IFERROR(VLOOKUP(A9,Sheet1!$E$3:$F$27,2,),"") -> Corrective | I9: =IFERROR(VLOOKUP(A9,Sheet1!$E$3:$G$27,3,0),"") -> Perbaikan Auto,pergantian relay,timer, yang berhubungan genset | J9: On Progress | K9: 46315 | L9: 46315 | M9: Done | N9: geser KKP124 ts cell down
A10: Cell down | B10: =IFERROR(VLOOKUP(A10,Sheet1!$E$3:$H$27,4,0),"") -> P1 | C10: KKP117 | D10: Sahrul Saputra | E10: =IFERROR(VLOOKUP(D10,Sheet1!$B$1:$C$45,2,0),"") -> TE | F10: Winda Sokenda | G10: =IFERROR(IFS(F10="Winda Sokenda","Barito Raya",F10="Doni Damara","Palangkaraya"),"") -> Barito Raya | H10: =IFERROR(VLOOKUP(A10,Sheet1!$E$3:$F$27,2,),"") -> Corrective | I10: =IFERROR(VLOOKUP(A10,Sheet1!$E$3:$G$27,3,0),"") -> Replace Optik,RRU/Soket Power/Replace GPS | J10: On Progress | K10: 46315 | L10: 46315 | M10: Pending | N10: Lanjut Besok, kondisi hujan d jalan
A11: Pengecekan Power | B11: =IFERROR(VLOOKUP(A11,Sheet1!$E$3:$H$27,4,0),"") -> P1 | C11: PRC225 (backup) | D11: Ahmad Muzakir | E11: =IFERROR(VLOOKUP(D11,Sheet1!$B$1:$C$45,2,0),"") -> MBP | F11: Winda Sokenda | G11: =IFERROR(IFS(F11="Winda Sokenda","Barito Raya",F11="Doni Damara","Palangkaraya"),"") -> Barito Raya | H11: =IFERROR(VLOOKUP(A11,Sheet1!$E$3:$F$27,2,),"") -> Preventive | I11: =IFERROR(VLOOKUP(A11,Sheet1!$E$3:$G$27,3,0),"") -> MCB trip/Power upnormal | J11: On Progress | K11: 46315 | L11: 46315 | M11: Done | N11: Backup PRC225
A12: Pengecekan Power | B12: =IFERROR(VLOOKUP(A12,Sheet1!$E$3:$H$27,4,0),"") -> P1 | C12: TML005 (Backup) | D12: Harun Nurasyid | E12: =IFERROR(VLOOKUP(D12,Sheet1!$B$1:$C$45,2,0),"") -> CME | F12: Winda Sokenda | G12: =IFERROR(IFS(F12="Winda Sokenda","Barito Raya",F12="Doni Damara","Palangkaraya"),"") -> Barito Raya | H12: =IFERROR(VLOOKUP(A12,Sheet1!$E$3:$F$27,2,),"") -> Preventive | I12: =IFERROR(VLOOKUP(A12,Sheet1!$E$3:$G$27,3,0),"") -> MCB trip/Power upnormal | J12: On Progress | K12: 46315 | L12: 46315 | M12: Done | N12: Standbay Pemadaman
A13: Pengecekan Power | B13: =IFERROR(VLOOKUP(A13,Sheet1!$E$3:$H$27,4,0),"") -> P1 | C13: KKP072 (backup) | D13: Nurhayat | E13: MBP | F13: Winda Sokenda | G13: =IFERROR(IFS(F13="Winda Sokenda","Barito Raya",F13="Doni Damara","Palangkaraya"),"") -> Barito Raya | H13: =IFERROR(VLOOKUP(A13,Sheet1!$E$3:$F$27,2,),"") -> Preventive | I13: =IFERROR(VLOOKUP(A13,Sheet1!$E$3:$G$27,3,0),"") -> MCB trip/Power upnormal | J13: On Progress | K13: 46315 | L13: 46315 | M13: Done | N13: Standbay Pemadaman
A14: Tshoot Genset | B14: =IFERROR(VLOOKUP(A14,Sheet1!$E$3:$H$27,4,0),"") -> P1 | C14: KKP305 | D14: Pujianto | E14: =IFERROR(VLOOKUP(D14,Sheet1!$B$1:$C$45,2,0),"") -> MBP | F14: Winda Sokenda | G14: =IFERROR(IFS(F14="Winda Sokenda","Barito Raya",F14="Doni Damara","Palangkaraya"),"") -> Barito Raya | H14: =IFERROR(VLOOKUP(A14,Sheet1!$E$3:$F$27,2,),"") -> Corrective | I14: =IFERROR(VLOOKUP(A14,Sheet1!$E$3:$G$27,3,0),"") -> Perbaikan Auto,pergantian relay,timer, yang berhubungan genset | J14: On Progress | K14: 46315 | L14: 46315 | M14: Done | N14: Backup KKP093
A15: Pengecekan Power | B15: =IFERROR(VLOOKUP(A15,Sheet1!$E$3:$H$27,4,0),"") -> P1 | C15: KKP065 (Backup) | D15: Alfi Syahri | E15: =IFERROR(VLOOKUP(D15,Sheet1!$B$1:$C$45,2,0),"") -> CME | F15: Winda Sokenda | G15: =IFERROR(IFS(F15="Winda Sokenda","Barito Raya",F15="Doni Damara","Palangkaraya"),"") -> Barito Raya | H15: =IFERROR(VLOOKUP(A15,Sheet1!$E$3:$F$27,2,),"") -> Preventive | I15: =IFERROR(VLOOKUP(A15,Sheet1!$E$3:$G$27,3,0),"") -> MCB trip/Power upnormal | J15: On Progress | K15: 46315 | L15: 46315 | M15: Done | N15: Standbay Pemadaman
A16: Pengecekan Power | B16: =IFERROR(VLOOKUP(A16,Sheet1!$E$3:$H$27,4,0),"") -> P1 | C16: MTW004 (Backup) | D16: Taklim | E16: MBP | F16: Winda Sokenda | G16: =IFERROR(IFS(F16="Winda Sokenda","Barito Raya",F16="Doni Damara","Palangkaraya"),"") -> Barito Raya | H16: =IFERROR(VLOOKUP(A16,Sheet1!$E$3:$F$27,2,),"") -> Preventive | I16: =IFERROR(VLOOKUP(A16,Sheet1!$E$3:$G$27,3,0),"") -> MCB trip/Power upnormal | J16: On Progress | K16: 46315 | L16: 46315 | M16: Done | N16: Backup MTW004
A17: Standby On Call | B17: =IFERROR(VLOOKUP(A17,Sheet1!$E$3:$H$27,4,0),"") -> P3 | D17: Riko setiadi | E17: =IFERROR(VLOOKUP(D17,Sheet1!$B$1:$C$45,2,0),"") -> PM | F17: Winda Sokenda | G17: =IFERROR(IFS(F17="Winda Sokenda","Barito Raya",F17="Doni Damara","Palangkaraya"),"") -> Barito Raya | H17: =IFERROR(VLOOKUP(A17,Sheet1!$E$3:$F$27,2,),"") -> Standby | I17: =IFERROR(VLOOKUP(A17,Sheet1!$E$3:$G$27,3,0),"") -> Standby On Call | J17: On Progress | K17: 46315 | L17: 46315 | M17: Done | N17: Kawal pengisian BBM & cek genset
A18: PM | B18: =IFERROR(VLOOKUP(A18,Sheet1!$E$3:$H$27,4,0),"") -> P2 | C18: KKP007 | D18: Khilal dawai katiri | E18: =IFERROR(VLOOKUP(D18,Sheet1!$B$1:$C$45,2,0),"") -> MBP | F18: Winda Sokenda | G18: =IFERROR(IFS(F18="Winda Sokenda","Barito Raya",F18="Doni Damara","Palangkaraya"),"") -> Barito Raya | H18: =IFERROR(VLOOKUP(A18,Sheet1!$E$3:$F$27,2,),"") -> Preventive | I18: =IFERROR(VLOOKUP(A18,Sheet1!$E$3:$G$27,3,0),"") -> Preventive Maintenance | J18: On Progress | K18: 46315 | L18: 46315 | M18: Pending | N18: PMS
A19: PM | B19: =IFERROR(VLOOKUP(A19,Sheet1!$E$3:$H$27,4,0),"") -> P2 | C19: PRC008 | D19: Riko setiadi | E19: =IFERROR(VLOOKUP(D19,Sheet1!$B$1:$C$45,2,0),"") -> PM | F19: Winda Sokenda | G19: =IFERROR(IFS(F19="Winda Sokenda","Barito Raya",F19="Doni Damara","Palangkaraya"),"") -> Barito Raya | H19: =IFERROR(VLOOKUP(A19,Sheet1!$E$3:$F$27,2,),"") -> Preventive | I19: =IFERROR(VLOOKUP(A19,Sheet1!$E$3:$G$27,3,0),"") -> Preventive Maintenance | J19: On Progress | K19: 46315 | L19: 46315 | M19: Waiting Update | N19: PMG
A20: Cell down | B20: =IFERROR(VLOOKUP(A20,Sheet1!$E$3:$H$27,4,0),"") -> P1 | C20: BNT006 | D20: Putra wardana | E20: =IFERROR(VLOOKUP(D20,Sheet1!$B$1:$C$45,2,0),"") -> TE | F20: Winda Sokenda | G20: =IFERROR(IFS(F20="Winda Sokenda","Barito Raya",F20="Doni Damara","Palangkaraya"),"") -> Barito Raya | H20: =IFERROR(VLOOKUP(A20,Sheet1!$E$3:$F$27,2,),"") -> Corrective | I20: =IFERROR(VLOOKUP(A20,Sheet1!$E$3:$G$27,3,0),"") -> Replace Optik,RRU/Soket Power/Replace GPS | J20: On Progress | K20: 46310 | L20: 46310 | M20: Waiting Update | N20: Replace RRU monitoring asap
A21: PM | B21: =IFERROR(VLOOKUP(A21,Sheet1!$E$3:$H$27,4,0),"") -> P2 | C21: AMT003 | D21: Sailillah | E21: =IFERROR(VLOOKUP(D21,Sheet1!$B$1:$C$45,2,0),"") -> TE | F21: Winda Sokenda | G21: =IFERROR(IFS(F21="Winda Sokenda","Barito Raya",F21="Doni Damara","Palangkaraya"),"") -> Barito Raya | H21: =IFERROR(VLOOKUP(A21,Sheet1!$E$3:$F$27,2,),"") -> Preventive | I21: =IFERROR(VLOOKUP(A21,Sheet1!$E$3:$G$27,3,0),"") -> Preventive Maintenance | J21: On Progress | K21: 46310 | L21: 46310 | M21: Waiting Update | N21: PMG, waiting ops akses susur sungai
A22: Pengecekan battrey | B22: =IFERROR(VLOOKUP(A22,Sheet1!$E$3:$H$27,4,0),"") -> P2 | C22: BNT006 | D22: Tiviansyah | E22: =IFERROR(VLOOKUP(D22,Sheet1!$B$1:$C$45,2,0),"") -> TE | F22: Winda Sokenda | G22: =IFERROR(IFS(F22="Winda Sokenda","Barito Raya",F22="Doni Damara","Palangkaraya"),"") -> Barito Raya | H22: =IFERROR(VLOOKUP(A22,Sheet1!$E$3:$F$27,2,),"") -> Preventive | I22: =IFERROR(VLOOKUP(A22,Sheet1!$E$3:$G$27,3,0),"") -> Pengukuran dan pengambilan data log serta input Gdoc BBT | J22: On Progress | K22: 46310 | L22: 46310 | M22: Waiting Update | N22: Replace RRU monitoring asap
A23: Standby On Call | B23: =IFERROR(VLOOKUP(A23,Sheet1!$E$3:$H$27,4,0),"") -> P3 | D23: munawir akhmad | E23: =IFERROR(VLOOKUP(D23,Sheet1!$B$1:$C$45,2,0),"") -> TE | F23: Winda Sokenda | G23: =IFERROR(IFS(F23="Winda Sokenda","Barito Raya",F23="Doni Damara","Palangkaraya"),"") -> Barito Raya | H23: =IFERROR(VLOOKUP(A23,Sheet1!$E$3:$F$27,2,),"") -> Standby | I23: =IFERROR(VLOOKUP(A23,Sheet1!$E$3:$G$27,3,0),"") -> Standby On Call | J23: On Progress | K23: 46310 | L23: 46310 | M23: Waiting Update | N23: Plan CO MTW180
A24: Site Down | B24: =IFERROR(VLOOKUP(A24,Sheet1!$E$3:$H$27,4,0),"") -> P1 | C24: PRC189 | D24: Murjani | E24: =IFERROR(VLOOKUP(D24,Sheet1!$B$1:$C$45,2,0),"") -> TE | F24: Winda Sokenda | G24: =IFERROR(IFS(F24="Winda Sokenda","Barito Raya",F24="Doni Damara","Palangkaraya"),"") -> Barito Raya | H24: =IFERROR(VLOOKUP(A24,Sheet1!$E$3:$F$27,2,),"") -> Corrective | I24: =IFERROR(VLOOKUP(A24,Sheet1!$E$3:$G$27,3,0),"") -> Pemadaman,MCB Trip,Transmisi problem | J24: On Progress | K24: 46310 | L24: 46310 | M24: Waiting Update | N24: Pembersihan VP
A25: Site Down | B25: =IFERROR(VLOOKUP(A25,Sheet1!$E$3:$H$27,4,0),"") -> P1 | C25: KKP159 | D25: Reynaldy Ricardo Putra | E25: =IFERROR(VLOOKUP(D25,Sheet1!$B$1:$C$45,2,0),"") -> TE | F25: Winda Sokenda | G25: =IFERROR(IFS(F25="Winda Sokenda","Barito Raya",F25="Doni Damara","Palangkaraya"),"") -> Barito Raya | H25: =IFERROR(VLOOKUP(A25,Sheet1!$E$3:$F$27,2,),"") -> Corrective | I25: =IFERROR(VLOOKUP(A25,Sheet1!$E$3:$G$27,3,0),"") -> Pemadaman,MCB Trip,Transmisi problem | J25: On Progress | K25: 46310 | L25: 46310 | M25: Waiting Update | N25: Cek power
A26: Pengecekan battrey | B26: =IFERROR(VLOOKUP(A26,Sheet1!$E$3:$H$27,4,0),"") -> P2 | C26: KKP113 | D26: Sahrul Saputra | E26: =IFERROR(VLOOKUP(D26,Sheet1!$B$1:$C$45,2,0),"") -> TE | F26: Winda Sokenda | G26: =IFERROR(IFS(F26="Winda Sokenda","Barito Raya",F26="Doni Damara","Palangkaraya"),"") -> Barito Raya | H26: =IFERROR(VLOOKUP(A26,Sheet1!$E$3:$F$27,2,),"") -> Preventive | I26: =IFERROR(VLOOKUP(A26,Sheet1!$E$3:$G$27,3,0),"") -> Pengukuran dan pengambilan data log serta input Gdoc BBT | J26: On Progress | K26: 46310 | L26: 46310 | M26: Waiting Update | N26: BBT 0
A27: Pengecekan Power | B27: =IFERROR(VLOOKUP(A27,Sheet1!$E$3:$H$27,4,0),"") -> P1 | C27: PRC200 (backup) | D27: Ahmad Muzakir | E27: =IFERROR(VLOOKUP(D27,Sheet1!$B$1:$C$45,2,0),"") -> MBP | F27: Winda Sokenda | G27: =IFERROR(IFS(F27="Winda Sokenda","Barito Raya",F27="Doni Damara","Palangkaraya"),"") -> Barito Raya | H27: =IFERROR(VLOOKUP(A27,Sheet1!$E$3:$F$27,2,),"") -> Preventive | I27: =IFERROR(VLOOKUP(A27,Sheet1!$E$3:$G$27,3,0),"") -> MCB trip/Power upnormal | J27: On Progress | K27: 46310 | L27: 46310 | M27: Waiting Update | N27: Standbay Pemadaman
A28: Pengecekan Power | B28: =IFERROR(VLOOKUP(A28,Sheet1!$E$3:$H$27,4,0),"") -> P1 | C28: TML005 (Backup) | D28: Harun Nurasyid | E28: =IFERROR(VLOOKUP(D28,Sheet1!$B$1:$C$45,2,0),"") -> CME | F28: Winda Sokenda | G28: =IFERROR(IFS(F28="Winda Sokenda","Barito Raya",F28="Doni Damara","Palangkaraya"),"") -> Barito Raya | H28: =IFERROR(VLOOKUP(A28,Sheet1!$E$3:$F$27,2,),"") -> Preventive | I28: =IFERROR(VLOOKUP(A28,Sheet1!$E$3:$G$27,3,0),"") -> MCB trip/Power upnormal | J28: On Progress | K28: 46310 | L28: 46310 | M28: Waiting Update | N28: Standbay Pemadaman
A29: Pengecekan Power | B29: =IFERROR(VLOOKUP(A29,Sheet1!$E$3:$H$27,4,0),"") -> P1 | C29: KKP072 (backup) | D29: Nurhayat | E29: MBP | F29: Winda Sokenda | G29: =IFERROR(IFS(F29="Winda Sokenda","Barito Raya",F29="Doni Damara","Palangkaraya"),"") -> Barito Raya | H29: =IFERROR(VLOOKUP(A29,Sheet1!$E$3:$F$27,2,),"") -> Preventive | I29: =IFERROR(VLOOKUP(A29,Sheet1!$E$3:$G$27,3,0),"") -> MCB trip/Power upnormal | J29: On Progress | K29: 46310 | L29: 46310 | M29: Waiting Update | N29: Standbay Pemadaman
A30: Repointing MW | B30: =IFERROR(VLOOKUP(A30,Sheet1!$E$3:$H$27,4,0),"") -> P1 | C30: KKP005 (backup) | D30: Pujianto | E30: =IFERROR(VLOOKUP(D30,Sheet1!$B$1:$C$45,2,0),"") -> MBP | F30: Winda Sokenda | G30: =IFERROR(IFS(F30="Winda Sokenda","Barito Raya",F30="Doni Damara","Palangkaraya"),"") -> Barito Raya | H30: =IFERROR(VLOOKUP(A30,Sheet1!$E$3:$F$27,2,),"") -> Corrective | I30: =IFERROR(VLOOKUP(A30,Sheet1!$E$3:$G$27,3,0),"") -> Impact BTS down / RX Level >70 / PL | J30: On Progress | K30: 46310 | L30: 46310 | M30: Waiting Update | N30: Standbay Pemadaman
A31: Penambahan Modul Recti | B31: =IFERROR(VLOOKUP(A31,Sheet1!$E$3:$H$27,4,0),"") -> P2 | C31: KKP065 | D31: Alfi Syahri | E31: =IFERROR(VLOOKUP(D31,Sheet1!$B$1:$C$45,2,0),"") -> CME | F31: Winda Sokenda | G31: =IFERROR(IFS(F31="Winda Sokenda","Barito Raya",F31="Doni Damara","Palangkaraya"),"") -> Barito Raya | H31: =IFERROR(VLOOKUP(A31,Sheet1!$E$3:$F$27,2,),"") -> Corrective | I31: =IFERROR(VLOOKUP(A31,Sheet1!$E$3:$G$27,3,0),"") -> Penambahan Modul Recti | J31: On Progress | K31: 46310 | L31: 46310 | M31: Waiting Update | N31: Replace APR
A32: Pengecekan Power | B32: =IFERROR(VLOOKUP(A32,Sheet1!$E$3:$H$27,4,0),"") -> P1 | C32: MTW004 (Backup) | D32: Taklim | E32: MBP | F32: Winda Sokenda | G32: =IFERROR(IFS(F32="Winda Sokenda","Barito Raya",F32="Doni Damara","Palangkaraya"),"") -> Barito Raya | H32: =IFERROR(VLOOKUP(A32,Sheet1!$E$3:$F$27,2,),"") -> Preventive | I32: =IFERROR(VLOOKUP(A32,Sheet1!$E$3:$G$27,3,0),"") -> MCB trip/Power upnormal | J32: On Progress | K32: 46310 | L32: 46310 | M32: Waiting Update | N32: Standbay Pemadaman
A33: Cell down | B33: =IFERROR(VLOOKUP(A33,Sheet1!$E$3:$H$27,4,0),"") -> P1 | C33: KKP146 | D33: Yahya Muhamad | E33: =IFERROR(VLOOKUP(D33,Sheet1!$B$1:$C$45,2,0),"") -> TE | F33: Winda Sokenda | G33: Barito Raya | H33: =IFERROR(VLOOKUP(A33,Sheet1!$E$3:$F$27,2,),"") -> Corrective | I33: =IFERROR(VLOOKUP(A33,Sheet1!$E$3:$G$27,3,0),"") -> Replace Optik,RRU/Soket Power/Replace GPS | J33: On Progress | K33: 46310 | L33: 46310 | M33: Waiting Update | N33: Cell Flicker
A34: PM | B34: =IFERROR(VLOOKUP(A34,Sheet1!$E$3:$H$27,4,0),"") -> P2 | C34: TML026 | D34: Khilal dawai katiri | E34: =IFERROR(VLOOKUP(D34,Sheet1!$B$1:$C$45,2,0),"") -> MBP | F34: Winda Sokenda | G34: Barito Raya | H34: =IFERROR(VLOOKUP(A34,Sheet1!$E$3:$F$27,2,),"") -> Preventive | I34: =IFERROR(VLOOKUP(A34,Sheet1!$E$3:$G$27,3,0),"") -> Preventive Maintenance | J34: On Progress | K34: 46310 | L34: 46310 | M34: Waiting Update | N34: PMS
A35: PM | B35: =IFERROR(VLOOKUP(A35,Sheet1!$E$3:$H$27,4,0),"") -> P2 | C35: PRC051 | D35: Riko setiadi | E35: =IFERROR(VLOOKUP(D35,Sheet1!$B$1:$C$45,2,0),"") -> PM | F35: Winda Sokenda | G35: Barito Raya | H35: =IFERROR(VLOOKUP(A35,Sheet1!$E$3:$F$27,2,),"") -> Preventive | I35: =IFERROR(VLOOKUP(A35,Sheet1!$E$3:$G$27,3,0),"") -> Preventive Maintenance | J35: Standby | K35: 46310 | L35: 46310 | M35: Waiting Update | N35: PMS
A36: Pengecekan battrey | B36: =IFERROR(VLOOKUP(A36,Sheet1!$E$3:$H$27,4,0),"") -> P2 | C36: BNT006 | D36: Putra wardana | E36: =IFERROR(VLOOKUP(D36,Sheet1!$B$1:$C$45,2,0),"") -> TE | F36: Winda Sokenda | G36: =IFERROR(IFS(F36="Winda Sokenda","Barito Raya",F36="Doni Damara","Palangkaraya"),"") -> Barito Raya | H36: =IFERROR(VLOOKUP(A36,Sheet1!$E$3:$F$27,2,),"") -> Preventive | I36: =IFERROR(VLOOKUP(A36,Sheet1!$E$3:$G$27,3,0),"") -> Pengukuran dan pengambilan data log serta input Gdoc BBT | J36: On Progress | K36: 46307 | L36: 46307 | M36: Done | N36: BBT 0
A37: Site Down | B37: =IFERROR(VLOOKUP(A37,Sheet1!$E$3:$H$27,4,0),"") -> P1 | C37: AMT003 | D37: Sailillah | E37: =IFERROR(VLOOKUP(D37,Sheet1!$B$1:$C$45,2,0),"") -> TE | F37: Winda Sokenda | G37: =IFERROR(IFS(F37="Winda Sokenda","Barito Raya",F37="Doni Damara","Palangkaraya"),"") -> Barito Raya | H37: =IFERROR(VLOOKUP(A37,Sheet1!$E$3:$F$27,2,),"") -> Corrective | I37: =IFERROR(VLOOKUP(A37,Sheet1!$E$3:$G$27,3,0),"") -> Pemadaman,MCB Trip,Transmisi problem | J37: On Progress | K37: 46307 | L37: 46307 | M37: Done | N37: Koordinasi to pjs
A38: Pengecekan battrey | B38: =IFERROR(VLOOKUP(A38,Sheet1!$E$3:$H$27,4,0),"") -> P2 | C38: MTW062 | D38: Tiviansyah | E38: =IFERROR(VLOOKUP(D38,Sheet1!$B$1:$C$45,2,0),"") -> TE | F38: Winda Sokenda | G38: =IFERROR(IFS(F38="Winda Sokenda","Barito Raya",F38="Doni Damara","Palangkaraya"),"") -> Barito Raya | H38: =IFERROR(VLOOKUP(A38,Sheet1!$E$3:$F$27,2,),"") -> Preventive | I38: =IFERROR(VLOOKUP(A38,Sheet1!$E$3:$G$27,3,0),"") -> Pengukuran dan pengambilan data log serta input Gdoc BBT | J38: On Progress | K38: 46307 | L38: 46307 | M38: Done | N38: BBT 0
A39: Pengecekan battrey | B39: =IFERROR(VLOOKUP(A39,Sheet1!$E$3:$H$27,4,0),"") -> P2 | C39: MTW088 | D39: munawir akhmad | E39: =IFERROR(VLOOKUP(D39,Sheet1!$B$1:$C$45,2,0),"") -> TE | F39: Winda Sokenda | G39: =IFERROR(IFS(F39="Winda Sokenda","Barito Raya",F39="Doni Damara","Palangkaraya"),"") -> Barito Raya | H39: =IFERROR(VLOOKUP(A39,Sheet1!$E$3:$F$27,2,),"") -> Preventive | I39: =IFERROR(VLOOKUP(A39,Sheet1!$E$3:$G$27,3,0),"") -> Pengukuran dan pengambilan data log serta input Gdoc BBT | J39: On Progress | K39: 46307 | L39: 46307 | M39: Done | N39: BBT 0
A40: Pengecekan Power | B40: =IFERROR(VLOOKUP(A40,Sheet1!$E$3:$H$27,4,0),"") -> P1 | C40: PRC005 | D40: Murjani | E40: =IFERROR(VLOOKUP(D40,Sheet1!$B$1:$C$45,2,0),"") -> TE | F40: Winda Sokenda | G40: =IFERROR(IFS(F40="Winda Sokenda","Barito Raya",F40="Doni Damara","Palangkaraya"),"") -> Barito Raya | H40: =IFERROR(VLOOKUP(A40,Sheet1!$E$3:$F$27,2,),"") -> Preventive | I40: =IFERROR(VLOOKUP(A40,Sheet1!$E$3:$G$27,3,0),"") -> MCB trip/Power upnormal | J40: On Progress | K40: 46307 | L40: 46307 | M40: Done
A41: Pengecekan Power | B41: =IFERROR(VLOOKUP(A41,Sheet1!$E$3:$H$27,4,0),"") -> P1 | C41: KKP093 | D41: Reynaldy Ricardo Putra | E41: =IFERROR(VLOOKUP(D41,Sheet1!$B$1:$C$45,2,0),"") -> TE | F41: Winda Sokenda | G41: =IFERROR(IFS(F41="Winda Sokenda","Barito Raya",F41="Doni Damara","Palangkaraya"),"") -> Barito Raya | H41: =IFERROR(VLOOKUP(A41,Sheet1!$E$3:$F$27,2,),"") -> Preventive | I41: =IFERROR(VLOOKUP(A41,Sheet1!$E$3:$G$27,3,0),"") -> MCB trip/Power upnormal | J41: On Progress | K41: 46307 | L41: 46307 | M41: Done | N41: BBT 0
A42: Pengecekan battrey | B42: =IFERROR(VLOOKUP(A42,Sheet1!$E$3:$H$27,4,0),"") -> P2 | C42: KKP036 | D42: Sahrul Saputra | E42: =IFERROR(VLOOKUP(D42,Sheet1!$B$1:$C$45,2,0),"") -> TE | F42: Winda Sokenda | G42: =IFERROR(IFS(F42="Winda Sokenda","Barito Raya",F42="Doni Damara","Palangkaraya"),"") -> Barito Raya | H42: =IFERROR(VLOOKUP(A42,Sheet1!$E$3:$F$27,2,),"") -> Preventive | I42: =IFERROR(VLOOKUP(A42,Sheet1!$E$3:$G$27,3,0),"") -> Pengukuran dan pengambilan data log serta input Gdoc BBT | J42: On Progress | K42: 46307 | L42: 46307 | M42: Done | N42: BBT 0
...

Sheet Datastudio
A1: =IFERROR(__xludf.DUMMYFUNCTION("IMPORTRANGE(""https://docs.google.com/spreadsheets/d/1_hyXprjSM1g4AdEhPoiMjyaBs29sh04zf_9ON8dHV1g/edit?gid"",""to do list!A3:A1015"")"),"Category Task") -> Category Task | B1: =IFERROR(__xludf.DUMMYFUNCTION("IMPORTRANGE(""https://docs.google.com/spreadsheets/d/1_hyXprjSM1g4AdEhPoiMjyaBs29sh04zf_9ON8dHV1g/edit?gid"",""to do list!B3:B1015"")"),"Prioritas") -> Prioritas | C1: =IFERROR(__xludf.DUMMYFUNCTION("IMPORTRANGE(""https://docs.google.com/spreadsheets/d/1_hyXprjSM1g4AdEhPoiMjyaBs29sh04zf_9ON8dHV1g/edit?gid"",""to do list!C3:C1015"")"),"Site ID") -> Site ID | D1: =IFERROR(__xludf.DUMMYFUNCTION("IMPORTRANGE(""https://docs.google.com/spreadsheets/d/1_hyXprjSM1g4AdEhPoiMjyaBs29sh04zf_9ON8dHV1g/edit?gid"",""to do list!D3:D1015"")"),"FME Name") -> FME Name | E1: =IFERROR(__xludf.DUMMYFUNCTION("IMPORTRANGE(""https://docs.google.com/spreadsheets/d/1_hyXprjSM1g4AdEhPoiMjyaBs29sh04zf_9ON8dHV1g/edit?gid"",""to do list!E3:E1015"")"),"Role") -> Role | F1: =IFERROR(__xludf.DUMMYFUNCTION("IMPORTRANGE(""https://docs.google.com/spreadsheets/d/1_hyXprjSM1g4AdEhPoiMjyaBs29sh04zf_9ON8dHV1g/edit?gid"",""to do list!F3:F1015"")"),"RTS Name") -> RTS Name | G1: =IFERROR(__xludf.DUMMYFUNCTION("IMPORTRANGE(""https://docs.google.com/spreadsheets/d/1_hyXprjSM1g4AdEhPoiMjyaBs29sh04zf_9ON8dHV1g/edit?gid"",""to do list!G3:G1015"")"),"Cluster") -> Cluster | H1: =IFERROR(__xludf.DUMMYFUNCTION("IMPORTRANGE(""https://docs.google.com/spreadsheets/d/1_hyXprjSM1g4AdEhPoiMjyaBs29sh04zf_9ON8dHV1g/edit?gid"",""to do list!H3:H1015"")"),"Category Activity") -> Category Activity | I1: =IFERROR(__xludf.DUMMYFUNCTION("IMPORTRANGE(""https://docs.google.com/spreadsheets/d/1_hyXprjSM1g4AdEhPoiMjyaBs29sh04zf_9ON8dHV1g/edit?gid"",""to do list!I3:I1015"")"),"Detail Activity") -> Detail Activity | J1: =IFERROR(__xludf.DUMMYFUNCTION("IMPORTRANGE(""https://docs.google.com/spreadsheets/d/1_hyXprjSM1g4AdEhPoiMjyaBs29sh04zf_9ON8dHV1g/edit?gid"",""to do list!J3:J1015"")"),"Activity") -> Activity | K1: =IFERROR(__xludf.DUMMYFUNCTION("IMPORTRANGE(""https://docs.google.com/spreadsheets/d/1_hyXprjSM1g4AdEhPoiMjyaBs29sh04zf_9ON8dHV1g/edit?gid"",""to do list!K3:K1015"")"),"Start Date") -> Start Date | L1: =IFERROR(__xludf.DUMMYFUNCTION("IMPORTRANGE(""https://docs.google.com/spreadsheets/d/1_hyXprjSM1g4AdEhPoiMjyaBs29sh04zf_9ON8dHV1g/edit?gid"",""to do list!L3:L1015"")"),"End Date") -> End Date | M1: =IFERROR(__xludf.DUMMYFUNCTION("IMPORTRANGE(""https://docs.google.com/spreadsheets/d/1_hyXprjSM1g4AdEhPoiMjyaBs29sh04zf_9ON8dHV1g/edit?gid"",""to do list!M3:M1015"")"),"Status Task") -> Status Task | N1: =IFERROR(__xludf.DUMMYFUNCTION("IMPORTRANGE(""https://docs.google.com/spreadsheets/d/1_hyXprjSM1g4AdEhPoiMjyaBs29sh04zf_9ON8dHV1g/edit?gid"",""to do list!N3:N1015"")"),"Remark") -> Remark | O1: Long | P1: Lat | Q1: Tanggal
A2: =IFERROR(__xludf.DUMMYFUNCTION("""COMPUTED_VALUE"""),"Standby On Call") -> Standby On Call | B2: =IFERROR(__xludf.DUMMYFUNCTION("""COMPUTED_VALUE"""),"P3") -> P3 | D2: =IFERROR(__xludf.DUMMYFUNCTION("""COMPUTED_VALUE"""),"Putra wardana") -> Putra wardana | E2: =IFERROR(__xludf.DUMMYFUNCTION("""COMPUTED_VALUE"""),"TE") -> TE | F2: =IFERROR(__xludf.DUMMYFUNCTION("""COMPUTED_VALUE"""),"Winda Sokenda") -> Winda Sokenda | G2: =IFERROR(__xludf.DUMMYFUNCTION("""COMPUTED_VALUE"""),"Barito Raya") -> Barito Raya | H2: =IFERROR(__xludf.DUMMYFUNCTION("""COMPUTED_VALUE"""),"Standby") -> Standby | I2: =IFERROR(__xludf.DUMMYFUNCTION("""COMPUTED_VALUE"""),"Standby On Call") -> Standby On Call | J2: =IFERROR(__xludf.DUMMYFUNCTION("""COMPUTED_VALUE"""),"Standby") -> Standby | K2: =IFERROR(__xludf.DUMMYFUNCTION("""COMPUTED_VALUE"""),46315.0) -> 46315 | L2: =IFERROR(__xludf.DUMMYFUNCTION("""COMPUTED_VALUE"""),46315.0) -> 46315 | M2: =IFERROR(__xludf.DUMMYFUNCTION("""COMPUTED_VALUE"""),"Done") -> Done | N2: =IFERROR(__xludf.DUMMYFUNCTION("""COMPUTED_VALUE"""),"Stanby") -> Stanby | O2: 113.38514 | P2: -1.3519 | Q2: =LEFT(K2,2) -> 20
A3: =IFERROR(__xludf.DUMMYFUNCTION("""COMPUTED_VALUE"""),"Pengecekan Power") -> Pengecekan Power | B3: =IFERROR(__xludf.DUMMYFUNCTION("""COMPUTED_VALUE"""),"P1") -> P1 | C3: =IFERROR(__xludf.DUMMYFUNCTION("""COMPUTED_VALUE"""),"NTH149") -> NTH149 | D3: =IFERROR(__xludf.DUMMYFUNCTION("""COMPUTED_VALUE"""),"Sailillah") -> Sailillah | E3: =IFERROR(__xludf.DUMMYFUNCTION("""COMPUTED_VALUE"""),"TE") -> TE | F3: =IFERROR(__xludf.DUMMYFUNCTION("""COMPUTED_VALUE"""),"Winda Sokenda") -> Winda Sokenda | G3: =IFERROR(__xludf.DUMMYFUNCTION("""COMPUTED_VALUE"""),"Barito Raya") -> Barito Raya | H3: =IFERROR(__xludf.DUMMYFUNCTION("""COMPUTED_VALUE"""),"Preventive") -> Preventive | I3: =IFERROR(__xludf.DUMMYFUNCTION("""COMPUTED_VALUE"""),"MCB trip/Power upnormal") -> MCB trip/Power upnormal | J3: =IFERROR(__xludf.DUMMYFUNCTION("""COMPUTED_VALUE"""),"On Progress") -> On Progress | K3: =IFERROR(__xludf.DUMMYFUNCTION("""COMPUTED_VALUE"""),46315.0) -> 46315 | L3: =IFERROR(__xludf.DUMMYFUNCTION("""COMPUTED_VALUE"""),46315.0) -> 46315 | M3: =IFERROR(__xludf.DUMMYFUNCTION("""COMPUTED_VALUE"""),"Done") -> Done | N3: =IFERROR(__xludf.DUMMYFUNCTION("""COMPUTED_VALUE"""),"Isi token & PMS done") -> Isi token & PMS done | O3: =IFERROR(VLOOKUP(C3,Sheet4!A3:F790,6,0),"") -> 11519868 | Q3: =LEFT(K3,2) -> 20
A4: =IFERROR(__xludf.DUMMYFUNCTION("""COMPUTED_VALUE"""),"Sick") -> Sick | B4: =IFERROR(__xludf.DUMMYFUNCTION("""COMPUTED_VALUE"""),"P3") -> P3 | D4: =IFERROR(__xludf.DUMMYFUNCTION("""COMPUTED_VALUE"""),"Tiviansyah") -> Tiviansyah | E4: =IFERROR(__xludf.DUMMYFUNCTION("""COMPUTED_VALUE"""),"TE") -> TE | F4: =IFERROR(__xludf.DUMMYFUNCTION("""COMPUTED_VALUE"""),"Winda Sokenda") -> Winda Sokenda | G4: =IFERROR(__xludf.DUMMYFUNCTION("""COMPUTED_VALUE"""),"Barito Raya") -> Barito Raya | H4: =IFERROR(__xludf.DUMMYFUNCTION("""COMPUTED_VALUE"""),"Sick") -> Sick | I4: =IFERROR(__xludf.DUMMYFUNCTION("""COMPUTED_VALUE"""),"Sick") -> Sick | J4: =IFERROR(__xludf.DUMMYFUNCTION("""COMPUTED_VALUE"""),"Standby") -> Standby | K4: =IFERROR(__xludf.DUMMYFUNCTION("""COMPUTED_VALUE"""),46315.0) -> 46315 | L4: =IFERROR(__xludf.DUMMYFUNCTION("""COMPUTED_VALUE"""),46315.0) -> 46315 | M4: =IFERROR(__xludf.DUMMYFUNCTION("""COMPUTED_VALUE"""),"Done") -> Done | N4: =IFERROR(__xludf.DUMMYFUNCTION("""COMPUTED_VALUE"""),"Izin sakit") -> Izin sakit | O4: =IFERROR(VLOOKUP(C4,Sheet4!A4:F791,6,0),"") | Q4: =LEFT(K4,2) -> 20
A5: =IFERROR(__xludf.DUMMYFUNCTION("""COMPUTED_VALUE"""),"Site Down") -> Site Down | B5: =IFERROR(__xludf.DUMMYFUNCTION("""COMPUTED_VALUE"""),"P1") -> P1 | C5: =IFERROR(__xludf.DUMMYFUNCTION("""COMPUTED_VALUE"""),"COH937") -> COH937 | D5: =IFERROR(__xludf.DUMMYFUNCTION("""COMPUTED_VALUE"""),"munawir akhmad") -> munawir akhmad | E5: =IFERROR(__xludf.DUMMYFUNCTION("""COMPUTED_VALUE"""),"TE") -> TE | F5: =IFERROR(__xludf.DUMMYFUNCTION("""COMPUTED_VALUE"""),"Winda Sokenda") -> Winda Sokenda | G5: =IFERROR(__xludf.DUMMYFUNCTION("""COMPUTED_VALUE"""),"Barito Raya") -> Barito Raya | H5: =IFERROR(__xludf.DUMMYFUNCTION("""COMPUTED_VALUE"""),"Corrective") -> Corrective | I5: =IFERROR(__xludf.DUMMYFUNCTION("""COMPUTED_VALUE"""),"Pemadaman,MCB Trip,Transmisi problem") -> Pemadaman,MCB Trip,Transmisi problem | J5: =IFERROR(__xludf.DUMMYFUNCTION("""COMPUTED_VALUE"""),"On Progress") -> On Progress | K5: =IFERROR(__xludf.DUMMYFUNCTION("""COMPUTED_VALUE"""),46315.0) -> 46315 | L5: =IFERROR(__xludf.DUMMYFUNCTION("""COMPUTED_VALUE"""),46315.0) -> 46315 | M5: =IFERROR(__xludf.DUMMYFUNCTION("""COMPUTED_VALUE"""),"Done") -> Done | N5: =IFERROR(__xludf.DUMMYFUNCTION("""COMPUTED_VALUE"""),"PLN off, kawal team telkom MTW248") -> PLN off, kawal team telkom MTW248 | O5: =IFERROR(VLOOKUP(C5,Sheet4!A5:F792,6,0),"") -> 11490638 | Q5: =LEFT(K5,2) -> 20
A6: =IFERROR(__xludf.DUMMYFUNCTION("""COMPUTED_VALUE"""),"Site Down") -> Site Down | B6: =IFERROR(__xludf.DUMMYFUNCTION("""COMPUTED_VALUE"""),"P1") -> P1 | C6: =IFERROR(__xludf.DUMMYFUNCTION("""COMPUTED_VALUE"""),"PRC038") -> PRC038 | D6: =IFERROR(__xludf.DUMMYFUNCTION("""COMPUTED_VALUE"""),"Murjani") -> Murjani | E6: =IFERROR(__xludf.DUMMYFUNCTION("""COMPUTED_VALUE"""),"TE") -> TE | F6: =IFERROR(__xludf.DUMMYFUNCTION("""COMPUTED_VALUE"""),"Winda Sokenda") -> Winda Sokenda | G6: =IFERROR(__xludf.DUMMYFUNCTION("""COMPUTED_VALUE"""),"Barito Raya") -> Barito Raya | H6: =IFERROR(__xludf.DUMMYFUNCTION("""COMPUTED_VALUE"""),"Corrective") -> Corrective | I6: =IFERROR(__xludf.DUMMYFUNCTION("""COMPUTED_VALUE"""),"Pemadaman,MCB Trip,Transmisi problem") -> Pemadaman,MCB Trip,Transmisi problem | J6: =IFERROR(__xludf.DUMMYFUNCTION("""COMPUTED_VALUE"""),"On Progress") -> On Progress | K6: =IFERROR(__xludf.DUMMYFUNCTION("""COMPUTED_VALUE"""),46315.0) -> 46315 | L6: =IFERROR(__xludf.DUMMYFUNCTION("""COMPUTED_VALUE"""),46315.0) -> 46315 | M6: =IFERROR(__xludf.DUMMYFUNCTION("""COMPUTED_VALUE"""),"Done") -> Done | N6: =IFERROR(__xludf.DUMMYFUNCTION("""COMPUTED_VALUE"""),"Replace RRU") -> Replace RRU | O6: =IFERROR(VLOOKUP(C6,Sheet4!A6:F793,6,0),"") -> 1145281 | Q6: =LEFT(K6,2) -> 20
A7: =IFERROR(__xludf.DUMMYFUNCTION("""COMPUTED_VALUE"""),"Tshoot Genset") -> Tshoot Genset | B7: =IFERROR(__xludf.DUMMYFUNCTION("""COMPUTED_VALUE"""),"P1") -> P1 | C7: =IFERROR(__xludf.DUMMYFUNCTION("""COMPUTED_VALUE"""),"KKP305") -> KKP305 | D7: =IFERROR(__xludf.DUMMYFUNCTION("""COMPUTED_VALUE"""),"Reynaldy Ricardo Putra") -> Reynaldy Ricardo Putra | E7: =IFERROR(__xludf.DUMMYFUNCTION("""COMPUTED_VALUE"""),"TE") -> TE | F7: =IFERROR(__xludf.DUMMYFUNCTION("""COMPUTED_VALUE"""),"Winda Sokenda") -> Winda Sokenda | G7: =IFERROR(__xludf.DUMMYFUNCTION("""COMPUTED_VALUE"""),"Barito Raya") -> Barito Raya | H7: =IFERROR(__xludf.DUMMYFUNCTION("""COMPUTED_VALUE"""),"Corrective") -> Corrective | I7: =IFERROR(__xludf.DUMMYFUNCTION("""COMPUTED_VALUE"""),"Perbaikan Auto,pergantian relay,timer, yang berhubungan genset") -> Perbaikan Auto,pergantian relay,timer, yang berhubungan genset | J7: =IFERROR(__xludf.DUMMYFUNCTION("""COMPUTED_VALUE"""),"On Progress") -> On Progress | K7: =IFERROR(__xludf.DUMMYFUNCTION("""COMPUTED_VALUE"""),46315.0) -> 46315 | L7: =IFERROR(__xludf.DUMMYFUNCTION("""COMPUTED_VALUE"""),46315.0) -> 46315 | M7: =IFERROR(__xludf.DUMMYFUNCTION("""COMPUTED_VALUE"""),"Done") -> Done | N7: =IFERROR(__xludf.DUMMYFUNCTION("""COMPUTED_VALUE"""),"geser KKP124 ts cell down") -> geser KKP124 ts cell down | O7: =IFERROR(VLOOKUP(C7,Sheet4!A7:F794,6,0),"") -> 11440769 | Q7: =LEFT(K7,2) -> 20
A8: =IFERROR(__xludf.DUMMYFUNCTION("""COMPUTED_VALUE"""),"Cell down") -> Cell down | B8: =IFERROR(__xludf.DUMMYFUNCTION("""COMPUTED_VALUE"""),"P1") -> P1 | C8: =IFERROR(__xludf.DUMMYFUNCTION("""COMPUTED_VALUE"""),"KKP117") -> KKP117 | D8: =IFERROR(__xludf.DUMMYFUNCTION("""COMPUTED_VALUE"""),"Sahrul Saputra") -> Sahrul Saputra | E8: =IFERROR(__xludf.DUMMYFUNCTION("""COMPUTED_VALUE"""),"TE") -> TE | F8: =IFERROR(__xludf.DUMMYFUNCTION("""COMPUTED_VALUE"""),"Winda Sokenda") -> Winda Sokenda | G8: =IFERROR(__xludf.DUMMYFUNCTION("""COMPUTED_VALUE"""),"Barito Raya") -> Barito Raya | H8: =IFERROR(__xludf.DUMMYFUNCTION("""COMPUTED_VALUE"""),"Corrective") -> Corrective | I8: =IFERROR(__xludf.DUMMYFUNCTION("""COMPUTED_VALUE"""),"Replace Optik,RRU/Soket Power/Replace GPS") -> Replace Optik,RRU/Soket Power/Replace GPS | J8: =IFERROR(__xludf.DUMMYFUNCTION("""COMPUTED_VALUE"""),"On Progress") -> On Progress | K8: =IFERROR(__xludf.DUMMYFUNCTION("""COMPUTED_VALUE"""),46315.0) -> 46315 | L8: =IFERROR(__xludf.DUMMYFUNCTION("""COMPUTED_VALUE"""),46315.0) -> 46315 | M8: =IFERROR(__xludf.DUMMYFUNCTION("""COMPUTED_VALUE"""),"Pending") -> Pending | N8: =IFERROR(__xludf.DUMMYFUNCTION("""COMPUTED_VALUE"""),"Lanjut Besok, kondisi hujan d jalan") -> Lanjut Besok, kondisi hujan d jalan | O8: =IFERROR(VLOOKUP(C8,Sheet4!A8:F795,6,0),"") -> 11448663 | Q8: =LEFT(K8,2) -> 20
A9: =IFERROR(__xludf.DUMMYFUNCTION("""COMPUTED_VALUE"""),"Pengecekan Power") -> Pengecekan Power | B9: =IFERROR(__xludf.DUMMYFUNCTION("""COMPUTED_VALUE"""),"P1") -> P1 | C9: =IFERROR(__xludf.DUMMYFUNCTION("""COMPUTED_VALUE"""),"PRC225 (backup)") -> PRC225 (backup) | D9: =IFERROR(__xludf.DUMMYFUNCTION("""COMPUTED_VALUE"""),"Ahmad Muzakir") -> Ahmad Muzakir | E9: =IFERROR(__xludf.DUMMYFUNCTION("""COMPUTED_VALUE"""),"MBP") -> MBP | F9: =IFERROR(__xludf.DUMMYFUNCTION("""COMPUTED_VALUE"""),"Winda Sokenda") -> Winda Sokenda | G9: =IFERROR(__xludf.DUMMYFUNCTION("""COMPUTED_VALUE"""),"Barito Raya") -> Barito Raya | H9: =IFERROR(__xludf.DUMMYFUNCTION("""COMPUTED_VALUE"""),"Preventive") -> Preventive | I9: =IFERROR(__xludf.DUMMYFUNCTION("""COMPUTED_VALUE"""),"MCB trip/Power upnormal") -> MCB trip/Power upnormal | J9: =IFERROR(__xludf.DUMMYFUNCTION("""COMPUTED_VALUE"""),"On Progress") -> On Progress | K9: =IFERROR(__xludf.DUMMYFUNCTION("""COMPUTED_VALUE"""),46315.0) -> 46315 | L9: =IFERROR(__xludf.DUMMYFUNCTION("""COMPUTED_VALUE"""),46315.0) -> 46315 | M9: =IFERROR(__xludf.DUMMYFUNCTION("""COMPUTED_VALUE"""),"Done") -> Done | N9: =IFERROR(__xludf.DUMMYFUNCTION("""COMPUTED_VALUE"""),"Backup PRC225") -> Backup PRC225 | O9: =IFERROR(VLOOKUP(C9,Sheet4!A9:F796,6,0),"") | Q9: =LEFT(K9,2) -> 20
A10: =IFERROR(__xludf.DUMMYFUNCTION("""COMPUTED_VALUE"""),"Pengecekan Power") -> Pengecekan Power | B10: =IFERROR(__xludf.DUMMYFUNCTION("""COMPUTED_VALUE"""),"P1") -> P1 | C10: =IFERROR(__xludf.DUMMYFUNCTION("""COMPUTED_VALUE"""),"TML005 (Backup)") -> TML005 (Backup) | D10: =IFERROR(__xludf.DUMMYFUNCTION("""COMPUTED_VALUE"""),"Harun Nurasyid") -> Harun Nurasyid | E10: =IFERROR(__xludf.DUMMYFUNCTION("""COMPUTED_VALUE"""),"CME") -> CME | F10: =IFERROR(__xludf.DUMMYFUNCTION("""COMPUTED_VALUE"""),"Winda Sokenda") -> Winda Sokenda | G10: =IFERROR(__xludf.DUMMYFUNCTION("""COMPUTED_VALUE"""),"Barito Raya") -> Barito Raya | H10: =IFERROR(__xludf.DUMMYFUNCTION("""COMPUTED_VALUE"""),"Preventive") -> Preventive | I10: =IFERROR(__xludf.DUMMYFUNCTION("""COMPUTED_VALUE"""),"MCB trip/Power upnormal") -> MCB trip/Power upnormal | J10: =IFERROR(__xludf.DUMMYFUNCTION("""COMPUTED_VALUE"""),"On Progress") -> On Progress | K10: =IFERROR(__xludf.DUMMYFUNCTION("""COMPUTED_VALUE"""),46315.0) -> 46315 | L10: =IFERROR(__xludf.DUMMYFUNCTION("""COMPUTED_VALUE"""),46315.0) -> 46315 | M10: =IFERROR(__xludf.DUMMYFUNCTION("""COMPUTED_VALUE"""),"Done") -> Done | N10: =IFERROR(__xludf.DUMMYFUNCTION("""COMPUTED_VALUE"""),"Standbay Pemadaman") -> Standbay Pemadaman | O10: =IFERROR(VLOOKUP(C10,Sheet4!A10:F797,6,0),"") | Q10: =LEFT(K10,2) -> 20
A11: =IFERROR(__xludf.DUMMYFUNCTION("""COMPUTED_VALUE"""),"Pengecekan Power") -> Pengecekan Power | B11: =IFERROR(__xludf.DUMMYFUNCTION("""COMPUTED_VALUE"""),"P1") -> P1 | C11: =IFERROR(__xludf.DUMMYFUNCTION("""COMPUTED_VALUE"""),"KKP072 (backup)") -> KKP072 (backup) | D11: =IFERROR(__xludf.DUMMYFUNCTION("""COMPUTED_VALUE"""),"Nurhayat") -> Nurhayat | E11: =IFERROR(__xludf.DUMMYFUNCTION("""COMPUTED_VALUE"""),"MBP") -> MBP | F11: =IFERROR(__xludf.DUMMYFUNCTION("""COMPUTED_VALUE"""),"Winda Sokenda") -> Winda Sokenda | G11: =IFERROR(__xludf.DUMMYFUNCTION("""COMPUTED_VALUE"""),"Barito Raya") -> Barito Raya | H11: =IFERROR(__xludf.DUMMYFUNCTION("""COMPUTED_VALUE"""),"Preventive") -> Preventive | I11: =IFERROR(__xludf.DUMMYFUNCTION("""COMPUTED_VALUE"""),"MCB trip/Power upnormal") -> MCB trip/Power upnormal | J11: =IFERROR(__xludf.DUMMYFUNCTION("""COMPUTED_VALUE"""),"On Progress") -> On Progress | K11: =IFERROR(__xludf.DUMMYFUNCTION("""COMPUTED_VALUE"""),46315.0) -> 46315 | L11: =IFERROR(__xludf.DUMMYFUNCTION("""COMPUTED_VALUE"""),46315.0) -> 46315 | M11: =IFERROR(__xludf.DUMMYFUNCTION("""COMPUTED_VALUE"""),"Done") -> Done | N11: =IFERROR(__xludf.DUMMYFUNCTION("""COMPUTED_VALUE"""),"Standbay Pemadaman") -> Standbay Pemadaman | O11: =IFERROR(VLOOKUP(C11,Sheet4!A11:F798,6,0),"") | Q11: =LEFT(K11,2) -> 20
A12: =IFERROR(__xludf.DUMMYFUNCTION("""COMPUTED_VALUE"""),"Tshoot Genset") -> Tshoot Genset | B12: =IFERROR(__xludf.DUMMYFUNCTION("""COMPUTED_VALUE"""),"P1") -> P1 | C12: =IFERROR(__xludf.DUMMYFUNCTION("""COMPUTED_VALUE"""),"KKP305") -> KKP305 | D12: =IFERROR(__xludf.DUMMYFUNCTION("""COMPUTED_VALUE"""),"Pujianto") -> Pujianto | E12: =IFERROR(__xludf.DUMMYFUNCTION("""COMPUTED_VALUE"""),"MBP") -> MBP | F12: =IFERROR(__xludf.DUMMYFUNCTION("""COMPUTED_VALUE"""),"Winda Sokenda") -> Winda Sokenda | G12: =IFERROR(__xludf.DUMMYFUNCTION("""COMPUTED_VALUE"""),"Barito Raya") -> Barito Raya | H12: =IFERROR(__xludf.DUMMYFUNCTION("""COMPUTED_VALUE"""),"Corrective") -> Corrective | I12: =IFERROR(__xludf.DUMMYFUNCTION("""COMPUTED_VALUE"""),"Perbaikan Auto,pergantian relay,timer, yang berhubungan genset") -> Perbaikan Auto,pergantian relay,timer, yang berhubungan genset | J12: =IFERROR(__xludf.DUMMYFUNCTION("""COMPUTED_VALUE"""),"On Progress") -> On Progress | K12: =IFERROR(__xludf.DUMMYFUNCTION("""COMPUTED_VALUE"""),46315.0) -> 46315 | L12: =IFERROR(__xludf.DUMMYFUNCTION("""COMPUTED_VALUE"""),46315.0) -> 46315 | M12: =IFERROR(__xludf.DUMMYFUNCTION("""COMPUTED_VALUE"""),"Done") -> Done | N12: =IFERROR(__xludf.DUMMYFUNCTION("""COMPUTED_VALUE"""),"Backup KKP093") -> Backup KKP093 | O12: =IFERROR(VLOOKUP(C12,Sheet4!A12:F799,6,0),"") -> 11440769 | Q12: =LEFT(K12,2) -> 20
A13: =IFERROR(__xludf.DUMMYFUNCTION("""COMPUTED_VALUE"""),"Pengecekan Power") -> Pengecekan Power | B13: =IFERROR(__xludf.DUMMYFUNCTION("""COMPUTED_VALUE"""),"P1") -> P1 | C13: =IFERROR(__xludf.DUMMYFUNCTION("""COMPUTED_VALUE"""),"KKP065 (Backup)") -> KKP065 (Backup) | D13: =IFERROR(__xludf.DUMMYFUNCTION("""COMPUTED_VALUE"""),"Alfi Syahri") -> Alfi Syahri | E13: =IFERROR(__xludf.DUMMYFUNCTION("""COMPUTED_VALUE"""),"CME") -> CME | F13: =IFERROR(__xludf.DUMMYFUNCTION("""COMPUTED_VALUE"""),"Winda Sokenda") -> Winda Sokenda | G13: =IFERROR(__xludf.DUMMYFUNCTION("""COMPUTED_VALUE"""),"Barito Raya") -> Barito Raya | H13: =IFERROR(__xludf.DUMMYFUNCTION("""COMPUTED_VALUE"""),"Preventive") -> Preventive | I13: =IFERROR(__xludf.DUMMYFUNCTION("""COMPUTED_VALUE"""),"MCB trip/Power upnormal") -> MCB trip/Power upnormal | J13: =IFERROR(__xludf.DUMMYFUNCTION("""COMPUTED_VALUE"""),"On Progress") -> On Progress | K13: =IFERROR(__xludf.DUMMYFUNCTION("""COMPUTED_VALUE"""),46315.0) -> 46315 | L13: =IFERROR(__xludf.DUMMYFUNCTION("""COMPUTED_VALUE"""),46315.0) -> 46315 | M13: =IFERROR(__xludf.DUMMYFUNCTION("""COMPUTED_VALUE"""),"Done") -> Done | N13: =IFERROR(__xludf.DUMMYFUNCTION("""COMPUTED_VALUE"""),"Standbay Pemadaman") -> Standbay Pemadaman | O13: =IFERROR(VLOOKUP(C13,Sheet4!A13:F800,6,0),"") | Q13: =LEFT(K13,2) -> 20
A14: =IFERROR(__xludf.DUMMYFUNCTION("""COMPUTED_VALUE"""),"Pengecekan Power") -> Pengecekan Power | B14: =IFERROR(__xludf.DUMMYFUNCTION("""COMPUTED_VALUE"""),"P1") -> P1 | C14: =IFERROR(__xludf.DUMMYFUNCTION("""COMPUTED_VALUE"""),"MTW004 (Backup)") -> MTW004 (Backup) | D14: =IFERROR(__xludf.DUMMYFUNCTION("""COMPUTED_VALUE"""),"Taklim") -> Taklim | E14: =IFERROR(__xludf.DUMMYFUNCTION("""COMPUTED_VALUE"""),"MBP") -> MBP | F14: =IFERROR(__xludf.DUMMYFUNCTION("""COMPUTED_VALUE"""),"Winda Sokenda") -> Winda Sokenda | G14: =IFERROR(__xludf.DUMMYFUNCTION("""COMPUTED_VALUE"""),"Barito Raya") -> Barito Raya | H14: =IFERROR(__xludf.DUMMYFUNCTION("""COMPUTED_VALUE"""),"Preventive") -> Preventive | I14: =IFERROR(__xludf.DUMMYFUNCTION("""COMPUTED_VALUE"""),"MCB trip/Power upnormal") -> MCB trip/Power upnormal | J14: =IFERROR(__xludf.DUMMYFUNCTION("""COMPUTED_VALUE"""),"On Progress") -> On Progress | K14: =IFERROR(__xludf.DUMMYFUNCTION("""COMPUTED_VALUE"""),46315.0) -> 46315 | L14: =IFERROR(__xludf.DUMMYFUNCTION("""COMPUTED_VALUE"""),46315.0) -> 46315 | M14: =IFERROR(__xludf.DUMMYFUNCTION("""COMPUTED_VALUE"""),"Done") -> Done | N14: =IFERROR(__xludf.DUMMYFUNCTION("""COMPUTED_VALUE"""),"Backup MTW004") -> Backup MTW004 | O14: =IFERROR(VLOOKUP(C14,Sheet4!A14:F801,6,0),"") | Q14: =LEFT(K14,2) -> 20
A15: =IFERROR(__xludf.DUMMYFUNCTION("""COMPUTED_VALUE"""),"Standby On Call") -> Standby On Call | B15: =IFERROR(__xludf.DUMMYFUNCTION("""COMPUTED_VALUE"""),"P3") -> P3 | D15: =IFERROR(__xludf.DUMMYFUNCTION("""COMPUTED_VALUE"""),"Riko setiadi") -> Riko setiadi | E15: =IFERROR(__xludf.DUMMYFUNCTION("""COMPUTED_VALUE"""),"PM") -> PM | F15: =IFERROR(__xludf.DUMMYFUNCTION("""COMPUTED_VALUE"""),"Winda Sokenda") -> Winda Sokenda | G15: =IFERROR(__xludf.DUMMYFUNCTION("""COMPUTED_VALUE"""),"Barito Raya") -> Barito Raya | H15: =IFERROR(__xludf.DUMMYFUNCTION("""COMPUTED_VALUE"""),"Standby") -> Standby | I15: =IFERROR(__xludf.DUMMYFUNCTION("""COMPUTED_VALUE"""),"Standby On Call") -> Standby On Call | J15: =IFERROR(__xludf.DUMMYFUNCTION("""COMPUTED_VALUE"""),"On Progress") -> On Progress | K15: =IFERROR(__xludf.DUMMYFUNCTION("""COMPUTED_VALUE"""),46315.0) -> 46315 | L15: =IFERROR(__xludf.DUMMYFUNCTION("""COMPUTED_VALUE"""),46315.0) -> 46315 | M15: =IFERROR(__xludf.DUMMYFUNCTION("""COMPUTED_VALUE"""),"Done") -> Done | N15: =IFERROR(__xludf.DUMMYFUNCTION("""COMPUTED_VALUE"""),"Kawal pengisian BBM & cek genset ") -> Kawal pengisian BBM & cek genset | O15: =IFERROR(VLOOKUP(C15,Sheet4!A15:F802,6,0),"") | Q15: =LEFT(K15,2) -> 20
A16: =IFERROR(__xludf.DUMMYFUNCTION("""COMPUTED_VALUE"""),"PM") -> PM | B16: =IFERROR(__xludf.DUMMYFUNCTION("""COMPUTED_VALUE"""),"P2") -> P2 | C16: =IFERROR(__xludf.DUMMYFUNCTION("""COMPUTED_VALUE"""),"KKP007") -> KKP007 | D16: =IFERROR(__xludf.DUMMYFUNCTION("""COMPUTED_VALUE"""),"Khilal dawai katiri") -> Khilal dawai katiri | E16: =IFERROR(__xludf.DUMMYFUNCTION("""COMPUTED_VALUE"""),"MBP") -> MBP | F16: =IFERROR(__xludf.DUMMYFUNCTION("""COMPUTED_VALUE"""),"Winda Sokenda") -> Winda Sokenda | G16: =IFERROR(__xludf.DUMMYFUNCTION("""COMPUTED_VALUE"""),"Barito Raya") -> Barito Raya | H16: =IFERROR(__xludf.DUMMYFUNCTION("""COMPUTED_VALUE"""),"Preventive") -> Preventive | I16: =IFERROR(__xludf.DUMMYFUNCTION("""COMPUTED_VALUE"""),"Preventive Maintenance") -> Preventive Maintenance | J16: =IFERROR(__xludf.DUMMYFUNCTION("""COMPUTED_VALUE"""),"On Progress") -> On Progress | K16: =IFERROR(__xludf.DUMMYFUNCTION("""COMPUTED_VALUE"""),46315.0) -> 46315 | L16: =IFERROR(__xludf.DUMMYFUNCTION("""COMPUTED_VALUE"""),46315.0) -> 46315 | M16: =IFERROR(__xludf.DUMMYFUNCTION("""COMPUTED_VALUE"""),"Pending") -> Pending | N16: =IFERROR(__xludf.DUMMYFUNCTION("""COMPUTED_VALUE"""),"PMS") -> PMS | O16: =IFERROR(VLOOKUP(C16,Sheet4!A16:F803,6,0),"") -> 11447972 | Q16: =LEFT(K16,2) -> 20
A17: =IFERROR(__xludf.DUMMYFUNCTION("""COMPUTED_VALUE"""),"PM") -> PM | B17: =IFERROR(__xludf.DUMMYFUNCTION("""COMPUTED_VALUE"""),"P2") -> P2 | C17: =IFERROR(__xludf.DUMMYFUNCTION("""COMPUTED_VALUE"""),"PRC008") -> PRC008 | D17: =IFERROR(__xludf.DUMMYFUNCTION("""COMPUTED_VALUE"""),"Riko setiadi") -> Riko setiadi | E17: =IFERROR(__xludf.DUMMYFUNCTION("""COMPUTED_VALUE"""),"PM") -> PM | F17: =IFERROR(__xludf.DUMMYFUNCTION("""COMPUTED_VALUE"""),"Winda Sokenda") -> Winda Sokenda | G17: =IFERROR(__xludf.DUMMYFUNCTION("""COMPUTED_VALUE"""),"Barito Raya") -> Barito Raya | H17: =IFERROR(__xludf.DUMMYFUNCTION("""COMPUTED_VALUE"""),"Preventive") -> Preventive | I17: =IFERROR(__xludf.DUMMYFUNCTION("""COMPUTED_VALUE"""),"Preventive Maintenance") -> Preventive Maintenance | J17: =IFERROR(__xludf.DUMMYFUNCTION("""COMPUTED_VALUE"""),"On Progress") -> On Progress | K17: =IFERROR(__xludf.DUMMYFUNCTION("""COMPUTED_VALUE"""),46315.0) -> 46315 | L17: =IFERROR(__xludf.DUMMYFUNCTION("""COMPUTED_VALUE"""),46315.0) -> 46315 | M17: =IFERROR(__xludf.DUMMYFUNCTION("""COMPUTED_VALUE"""),"Waiting Update") -> Waiting Update | N17: =IFERROR(__xludf.DUMMYFUNCTION("""COMPUTED_VALUE"""),"PMG") -> PMG | O17: =IFERROR(VLOOKUP(C17,Sheet4!A17:F804,6,0),"") -> 11473414 | Q17: =LEFT(K17,2) -> 20
A18: =IFERROR(__xludf.DUMMYFUNCTION("""COMPUTED_VALUE"""),"Cell down") -> Cell down | B18: =IFERROR(__xludf.DUMMYFUNCTION("""COMPUTED_VALUE"""),"P1") -> P1 | C18: =IFERROR(__xludf.DUMMYFUNCTION("""COMPUTED_VALUE"""),"BNT006") -> BNT006 | D18: =IFERROR(__xludf.DUMMYFUNCTION("""COMPUTED_VALUE"""),"Putra wardana") -> Putra wardana | E18: =IFERROR(__xludf.DUMMYFUNCTION("""COMPUTED_VALUE"""),"TE") -> TE | F18: =IFERROR(__xludf.DUMMYFUNCTION("""COMPUTED_VALUE"""),"Winda Sokenda") -> Winda Sokenda | G18: =IFERROR(__xludf.DUMMYFUNCTION("""COMPUTED_VALUE"""),"Barito Raya") -> Barito Raya | H18: =IFERROR(__xludf.DUMMYFUNCTION("""COMPUTED_VALUE"""),"Corrective") -> Corrective | I18: =IFERROR(__xludf.DUMMYFUNCTION("""COMPUTED_VALUE"""),"Replace Optik,RRU/Soket Power/Replace GPS") -> Replace Optik,RRU/Soket Power/Replace GPS | J18: =IFERROR(__xludf.DUMMYFUNCTION("""COMPUTED_VALUE"""),"On Progress") -> On Progress | K18: =IFERROR(__xludf.DUMMYFUNCTION("""COMPUTED_VALUE"""),46310.0) -> 46310 | L18: =IFERROR(__xludf.DUMMYFUNCTION("""COMPUTED_VALUE"""),46310.0) -> 46310 | M18: =IFERROR(__xludf.DUMMYFUNCTION("""COMPUTED_VALUE"""),"Waiting Update") -> Waiting Update | N18: =IFERROR(__xludf.DUMMYFUNCTION("""COMPUTED_VALUE"""),"Replace RRU monitoring asap") -> Replace RRU monitoring asap | O18: =IFERROR(VLOOKUP(C18,Sheet4!A18:F805,6,0),"") -> 11505932 | Q18: =LEFT(K18,2) -> 15
A19: =IFERROR(__xludf.DUMMYFUNCTION("""COMPUTED_VALUE"""),"PM") -> PM | B19: =IFERROR(__xludf.DUMMYFUNCTION("""COMPUTED_VALUE"""),"P2") -> P2 | C19: =IFERROR(__xludf.DUMMYFUNCTION("""COMPUTED_VALUE"""),"AMT003") -> AMT003 | D19: =IFERROR(__xludf.DUMMYFUNCTION("""COMPUTED_VALUE"""),"Sailillah") -> Sailillah | E19: =IFERROR(__xludf.DUMMYFUNCTION("""COMPUTED_VALUE"""),"TE") -> TE | F19: =IFERROR(__xludf.DUMMYFUNCTION("""COMPUTED_VALUE"""),"Winda Sokenda") -> Winda Sokenda | G19: =IFERROR(__xludf.DUMMYFUNCTION("""COMPUTED_VALUE"""),"Barito Raya") -> Barito Raya | H19: =IFERROR(__xludf.DUMMYFUNCTION("""COMPUTED_VALUE"""),"Preventive") -> Preventive | I19: =IFERROR(__xludf.DUMMYFUNCTION("""COMPUTED_VALUE"""),"Preventive Maintenance") -> Preventive Maintenance | J19: =IFERROR(__xludf.DUMMYFUNCTION("""COMPUTED_VALUE"""),"On Progress") -> On Progress | K19: =IFERROR(__xludf.DUMMYFUNCTION("""COMPUTED_VALUE"""),46310.0) -> 46310 | L19: =IFERROR(__xludf.DUMMYFUNCTION("""COMPUTED_VALUE"""),46310.0) -> 46310 | M19: =IFERROR(__xludf.DUMMYFUNCTION("""COMPUTED_VALUE"""),"Waiting Update") -> Waiting Update | N19: =IFERROR(__xludf.DUMMYFUNCTION("""COMPUTED_VALUE"""),"PMG, waiting ops akses susur sungai") -> PMG, waiting ops akses susur sungai | O19: =IFERROR(VLOOKUP(C19,Sheet4!A19:F806,6,0),"") -> 11491403 | Q19: =LEFT(K19,2) -> 15
A20: =IFERROR(__xludf.DUMMYFUNCTION("""COMPUTED_VALUE"""),"Pengecekan battrey") -> Pengecekan battrey | B20: =IFERROR(__xludf.DUMMYFUNCTION("""COMPUTED_VALUE"""),"P2") -> P2 | C20: =IFERROR(__xludf.DUMMYFUNCTION("""COMPUTED_VALUE"""),"BNT006") -> BNT006 | D20: =IFERROR(__xludf.DUMMYFUNCTION("""COMPUTED_VALUE"""),"Tiviansyah") -> Tiviansyah | E20: =IFERROR(__xludf.DUMMYFUNCTION("""COMPUTED_VALUE"""),"TE") -> TE | F20: =IFERROR(__xludf.DUMMYFUNCTION("""COMPUTED_VALUE"""),"Winda Sokenda") -> Winda Sokenda | G20: =IFERROR(__xludf.DUMMYFUNCTION("""COMPUTED_VALUE"""),"Barito Raya") -> Barito Raya | H20: =IFERROR(__xludf.DUMMYFUNCTION("""COMPUTED_VALUE"""),"Preventive") -> Preventive | I20: =IFERROR(__xludf.DUMMYFUNCTION("""COMPUTED_VALUE"""),"Pengukuran dan pengambilan data log serta input Gdoc BBT") -> Pengukuran dan pengambilan data log serta input Gdoc BBT | J20: =IFERROR(__xludf.DUMMYFUNCTION("""COMPUTED_VALUE"""),"On Progress") -> On Progress | K20: =IFERROR(__xludf.DUMMYFUNCTION("""COMPUTED_VALUE"""),46310.0) -> 46310 | L20: =IFERROR(__xludf.DUMMYFUNCTION("""COMPUTED_VALUE"""),46310.0) -> 46310 | M20: =IFERROR(__xludf.DUMMYFUNCTION("""COMPUTED_VALUE"""),"Waiting Update") -> Waiting Update | N20: =IFERROR(__xludf.DUMMYFUNCTION("""COMPUTED_VALUE"""),"Replace RRU monitoring asap") -> Replace RRU monitoring asap | O20: =IFERROR(VLOOKUP(C20,Sheet4!A20:F807,6,0),"") -> 11505932 | Q20: =LEFT(K20,2) -> 15
A21: =IFERROR(__xludf.DUMMYFUNCTION("""COMPUTED_VALUE"""),"Standby On Call") -> Standby On Call | B21: =IFERROR(__xludf.DUMMYFUNCTION("""COMPUTED_VALUE"""),"P3") -> P3 | D21: =IFERROR(__xludf.DUMMYFUNCTION("""COMPUTED_VALUE"""),"munawir akhmad") -> munawir akhmad | E21: =IFERROR(__xludf.DUMMYFUNCTION("""COMPUTED_VALUE"""),"TE") -> TE | F21: =IFERROR(__xludf.DUMMYFUNCTION("""COMPUTED_VALUE"""),"Winda Sokenda") -> Winda Sokenda | G21: =IFERROR(__xludf.DUMMYFUNCTION("""COMPUTED_VALUE"""),"Barito Raya") -> Barito Raya | H21: =IFERROR(__xludf.DUMMYFUNCTION("""COMPUTED_VALUE"""),"Standby") -> Standby | I21: =IFERROR(__xludf.DUMMYFUNCTION("""COMPUTED_VALUE"""),"Standby On Call") -> Standby On Call | J21: =IFERROR(__xludf.DUMMYFUNCTION("""COMPUTED_VALUE"""),"On Progress") -> On Progress | K21: =IFERROR(__xludf.DUMMYFUNCTION("""COMPUTED_VALUE"""),46310.0) -> 46310 | L21: =IFERROR(__xludf.DUMMYFUNCTION("""COMPUTED_VALUE"""),46310.0) -> 46310 | M21: =IFERROR(__xludf.DUMMYFUNCTION("""COMPUTED_VALUE"""),"Waiting Update") -> Waiting Update | N21: =IFERROR(__xludf.DUMMYFUNCTION("""COMPUTED_VALUE"""),"Plan CO MTW180") -> Plan CO MTW180 | O21: =IFERROR(VLOOKUP(C21,Sheet4!A21:F808,6,0),"") | Q21: =LEFT(K21,2) -> 15
A22: =IFERROR(__xludf.DUMMYFUNCTION("""COMPUTED_VALUE"""),"Site Down") -> Site Down | B22: =IFERROR(__xludf.DUMMYFUNCTION("""COMPUTED_VALUE"""),"P1") -> P1 | C22: =IFERROR(__xludf.DUMMYFUNCTION("""COMPUTED_VALUE"""),"PRC189") -> PRC189 | D22: =IFERROR(__xludf.DUMMYFUNCTION("""COMPUTED_VALUE"""),"Murjani") -> Murjani | E22: =IFERROR(__xludf.DUMMYFUNCTION("""COMPUTED_VALUE"""),"TE") -> TE | F22: =IFERROR(__xludf.DUMMYFUNCTION("""COMPUTED_VALUE"""),"Winda Sokenda") -> Winda Sokenda | G22: =IFERROR(__xludf.DUMMYFUNCTION("""COMPUTED_VALUE"""),"Barito Raya") -> Barito Raya | H22: =IFERROR(__xludf.DUMMYFUNCTION("""COMPUTED_VALUE"""),"Corrective") -> Corrective | I22: =IFERROR(__xludf.DUMMYFUNCTION("""COMPUTED_VALUE"""),"Pemadaman,MCB Trip,Transmisi problem") -> Pemadaman,MCB Trip,Transmisi problem | J22: =IFERROR(__xludf.DUMMYFUNCTION("""COMPUTED_VALUE"""),"On Progress") -> On Progress | K22: =IFERROR(__xludf.DUMMYFUNCTION("""COMPUTED_VALUE"""),46310.0) -> 46310 | L22: =IFERROR(__xludf.DUMMYFUNCTION("""COMPUTED_VALUE"""),46310.0) -> 46310 | M22: =IFERROR(__xludf.DUMMYFUNCTION("""COMPUTED_VALUE"""),"Waiting Update") -> Waiting Update | N22: =IFERROR(__xludf.DUMMYFUNCTION("""COMPUTED_VALUE"""),"Pembersihan VP") -> Pembersihan VP | O22: =IFERROR(VLOOKUP(C22,Sheet4!A22:F809,6,0),"") -> 11463516 | Q22: =LEFT(K22,2) -> 15
A23: =IFERROR(__xludf.DUMMYFUNCTION("""COMPUTED_VALUE"""),"Site Down") -> Site Down | B23: =IFERROR(__xludf.DUMMYFUNCTION("""COMPUTED_VALUE"""),"P1") -> P1 | C23: =IFERROR(__xludf.DUMMYFUNCTION("""COMPUTED_VALUE"""),"KKP159") -> KKP159 | D23: =IFERROR(__xludf.DUMMYFUNCTION("""COMPUTED_VALUE"""),"Reynaldy Ricardo Putra") -> Reynaldy Ricardo Putra | E23: =IFERROR(__xludf.DUMMYFUNCTION("""COMPUTED_VALUE"""),"TE") -> TE | F23: =IFERROR(__xludf.DUMMYFUNCTION("""COMPUTED_VALUE"""),"Winda Sokenda") -> Winda Sokenda | G23: =IFERROR(__xludf.DUMMYFUNCTION("""COMPUTED_VALUE"""),"Barito Raya") -> Barito Raya | H23: =IFERROR(__xludf.DUMMYFUNCTION("""COMPUTED_VALUE"""),"Corrective") -> Corrective | I23: =IFERROR(__xludf.DUMMYFUNCTION("""COMPUTED_VALUE"""),"Pemadaman,MCB Trip,Transmisi problem") -> Pemadaman,MCB Trip,Transmisi problem | J23: =IFERROR(__xludf.DUMMYFUNCTION("""COMPUTED_VALUE"""),"On Progress") -> On Progress | K23: =IFERROR(__xludf.DUMMYFUNCTION("""COMPUTED_VALUE"""),46310.0) -> 46310 | L23: =IFERROR(__xludf.DUMMYFUNCTION("""COMPUTED_VALUE"""),46310.0) -> 46310 | M23: =IFERROR(__xludf.DUMMYFUNCTION("""COMPUTED_VALUE"""),"Waiting Update") -> Waiting Update | N23: =IFERROR(__xludf.DUMMYFUNCTION("""COMPUTED_VALUE"""),"Cek power") -> Cek power | O23: =IFERROR(VLOOKUP(C23,Sheet4!A23:F810,6,0),"") -> 11433822 | Q23: =LEFT(K23,2) -> 15
A24: =IFERROR(__xludf.DUMMYFUNCTION("""COMPUTED_VALUE"""),"Pengecekan battrey") -> Pengecekan battrey | B24: =IFERROR(__xludf.DUMMYFUNCTION("""COMPUTED_VALUE"""),"P2") -> P2 | C24: =IFERROR(__xludf.DUMMYFUNCTION("""COMPUTED_VALUE"""),"KKP113") -> KKP113 | D24: =IFERROR(__xludf.DUMMYFUNCTION("""COMPUTED_VALUE"""),"Sahrul Saputra") -> Sahrul Saputra | E24: =IFERROR(__xludf.DUMMYFUNCTION("""COMPUTED_VALUE"""),"TE") -> TE | F24: =IFERROR(__xludf.DUMMYFUNCTION("""COMPUTED_VALUE"""),"Winda Sokenda") -> Winda Sokenda | G24: =IFERROR(__xludf.DUMMYFUNCTION("""COMPUTED_VALUE"""),"Barito Raya") -> Barito Raya | H24: =IFERROR(__xludf.DUMMYFUNCTION("""COMPUTED_VALUE"""),"Preventive") -> Preventive | I24: =IFERROR(__xludf.DUMMYFUNCTION("""COMPUTED_VALUE"""),"Pengukuran dan pengambilan data log serta input Gdoc BBT") -> Pengukuran dan pengambilan data log serta input Gdoc BBT | J24: =IFERROR(__xludf.DUMMYFUNCTION("""COMPUTED_VALUE"""),"On Progress") -> On Progress | K24: =IFERROR(__xludf.DUMMYFUNCTION("""COMPUTED_VALUE"""),46310.0) -> 46310 | L24: =IFERROR(__xludf.DUMMYFUNCTION("""COMPUTED_VALUE"""),46310.0) -> 46310 | M24: =IFERROR(__xludf.DUMMYFUNCTION("""COMPUTED_VALUE"""),"Waiting Update") -> Waiting Update | N24: =IFERROR(__xludf.DUMMYFUNCTION("""COMPUTED_VALUE"""),"BBT 0") -> BBT 0 | O24: =IFERROR(VLOOKUP(C24,Sheet4!A24:F811,6,0),"") -> 11447436 | Q24: =LEFT(K24,2) -> 15
A25: =IFERROR(__xludf.DUMMYFUNCTION("""COMPUTED_VALUE"""),"Pengecekan Power") -> Pengecekan Power | B25: =IFERROR(__xludf.DUMMYFUNCTION("""COMPUTED_VALUE"""),"P1") -> P1 | C25: =IFERROR(__xludf.DUMMYFUNCTION("""COMPUTED_VALUE"""),"PRC200 (backup)") -> PRC200 (backup) | D25: =IFERROR(__xludf.DUMMYFUNCTION("""COMPUTED_VALUE"""),"Ahmad Muzakir") -> Ahmad Muzakir | E25: =IFERROR(__xludf.DUMMYFUNCTION("""COMPUTED_VALUE"""),"MBP") -> MBP | F25: =IFERROR(__xludf.DUMMYFUNCTION("""COMPUTED_VALUE"""),"Winda Sokenda") -> Winda Sokenda | G25: =IFERROR(__xludf.DUMMYFUNCTION("""COMPUTED_VALUE"""),"Barito Raya") -> Barito Raya | H25: =IFERROR(__xludf.DUMMYFUNCTION("""COMPUTED_VALUE"""),"Preventive") -> Preventive | I25: =IFERROR(__xludf.DUMMYFUNCTION("""COMPUTED_VALUE"""),"MCB trip/Power upnormal") -> MCB trip/Power upnormal | J25: =IFERROR(__xludf.DUMMYFUNCTION("""COMPUTED_VALUE"""),"On Progress") -> On Progress | K25: =IFERROR(__xludf.DUMMYFUNCTION("""COMPUTED_VALUE"""),46310.0) -> 46310 | L25: =IFERROR(__xludf.DUMMYFUNCTION("""COMPUTED_VALUE"""),46310.0) -> 46310 | M25: =IFERROR(__xludf.DUMMYFUNCTION("""COMPUTED_VALUE"""),"Waiting Update") -> Waiting Update | N25: =IFERROR(__xludf.DUMMYFUNCTION("""COMPUTED_VALUE"""),"Standbay Pemadaman") -> Standbay Pemadaman | O25: =IFERROR(VLOOKUP(C25,Sheet4!A25:F812,6,0),"") | Q25: =LEFT(K25,2) -> 15
